<?xml version="1.0" encoding="utf-8"?>
<robot
  name="manipulator_description">
  <link
    name="base_link">
    <inertial>
      <origin
        xyz="0.0338814628210099 0.000497720543275145 -0.00331359754353024"
        rpy="0 0 0" />
      <mass
        value="19.3716416296026" />
      <inertia
        ixx="0.248871888708118"
        ixy="3.36859319608728E-05"
        ixz="0.00193455041773922"
        iyy="0.153912861665241"
        iyz="-0.000522035171672044"
        izz="0.133072058737686" />
    </inertial>
    <visual>
      <origin
        xyz="0 0 0"
        rpy="0 0 0" />
      <geometry>
        <mesh
          filename="package://manipulator_description_pkg/meshes/base_link.stl" />
      </geometry>
      <material
        name="">
        <color
          rgba="0.647058823529412 0.619607843137255 0.588235294117647 1" />
      </material>
    </visual>
    <collision>
      <origin
        xyz="0 0 0"
        rpy="0 0 0" />
      <geometry>
        <mesh filename="package://manipulator_description_pkg/meshes/base_link.stl" />
      </geometry>
    </collision>
  </link>
  
  <link name="base_dummy"/>
  
  <joint name="joint_dummy" type="fixed">
  		<origin rpy="0.0 -1.57 0.0" xyz="0.0 0.0 0.0"/>
    	<parent link="base_dummy"/>
	   <child link="base_link"/>
  </joint>
  
  <link
    name="Link_1">
    <inertial>
      <origin
        xyz="0.00112019087217312 -0.0150996198212963 0.122987934263855"
        rpy="0 0 0" />
      <mass
        value="5.42002634678791" />
      <inertia
        ixx="0.0318090009424056"
        ixy="-0.000275449690746801"
        ixz="-0.000138372947778435"
        iyy="0.0393520505597679"
        iyz="0.00342085402867629"
        izz="0.0211820866094541" />
    </inertial>
    <visual>
      <origin
        xyz="0 0 0"
        rpy="0 0 0" />
      <geometry>
        <mesh
          filename="package://manipulator_description_pkg/meshes/Link_1.stl" />
      </geometry>
      <material
        name="">
        <color
          rgba="0.752941176470588 0.752941176470588 0.752941176470588 1" />
      </material>
    </visual>
    <collision>
      <origin
        xyz="0 0 0"
        rpy="0 0 0" />
      <geometry>
        <mesh
          filename="package://manipulator_description_pkg/meshes/Link_1.stl" />
      </geometry>
    </collision>
  </link>
  <joint
    name="J1"
    type="revolute">
    <origin
      xyz="0.2614 0 0"
      rpy="1.5707963267949 0 1.5707963267949" />
    <parent
      link="base_link" />
    <child
      link="Link_1" />
    <axis
      xyz="0 0 -1" />
    <limit
      lower="-3.14"
      upper="3.14"
      effort="0"
      velocity="1.0" />
  </joint>
  <link
    name="Link_2">
    <inertial>
      <origin
        xyz="0.11503851762498 0.00956850888648267 0.0168648159925938"
        rpy="0 0 0" />
      <mass
        value="4.49542625085589" />
      <inertia
        ixx="0.0114606826201459"
        ixy="-0.00309283549883583"
        ixz="0.00444711580402875"
        iyy="0.034964499365664"
        iyz="0.000519654260093934"
        izz="0.0354389928704922" />
    </inertial>
    <visual>
      <origin
        xyz="0 0 0"
        rpy="0 0 0" />
      <geometry>
        <mesh
          filename="package://manipulator_description_pkg/meshes/Link_2.stl" />
      </geometry>
      <material
        name="">
        <color
          rgba="0.752941176470588 0.752941176470588 0.752941176470588 1" />
      </material>
    </visual>
    <collision>
      <origin
        xyz="0 0 0"
        rpy="0 0 0" />
      <geometry>
        <mesh
          filename="package://manipulator_description_pkg/meshes/Link_2.stl" />
      </geometry>
    </collision>
  </link>
  <joint
    name="J2"
    type="revolute">
    <origin
      xyz="0 0 0.22"
      rpy="1.5707963267949 -1.5707963267949 0" />
    <parent
      link="Link_1" />
    <child
      link="Link_2" />
    <axis
      xyz="0 0 1" />
    <limit
      lower="-1.57"
      upper="1.57"
      effort="0"
      velocity="1.0" />
  </joint>
  <link
    name="Link_3">
    <inertial>
      <origin
        xyz="-0.103763666826494 0.0101780805498739 -0.0184021205755318"
        rpy="0 0 0" />
      <mass
        value="3.16096272805723" />
      <inertia
        ixx="0.00685911518751925"
        ixy="0.00137691161825123"
        ixz="0.00205391889116741"
        iyy="0.0160897968555814"
        iyz="-0.000262824639901742"
        izz="0.0158486555956697" />
    </inertial>
    <visual>
      <origin
        xyz="0 0 0"
        rpy="0 0 0" />
      <geometry>
        <mesh
          filename="package://manipulator_description_pkg/meshes/Link_3.stl" />
      </geometry>
      <material
        name="">
        <color
          rgba="0.752941176470588 0.752941176470588 0.752941176470588 1" />
      </material>
    </visual>
    <collision>
      <origin
        xyz="0 0 0"
        rpy="0 0 0" />
      <geometry>
        <mesh
          filename="package://manipulator_description_pkg/meshes/Link_3.stl" />
      </geometry>
    </collision>
  </link>
  <joint
    name="J3"
    type="revolute">
    <origin
      xyz="0.251 0 0"
      rpy="1.5707963267949 0 -3.14159265358979" />
    <parent
      link="Link_2" />
    <child
      link="Link_3" />
    <axis
      xyz="0 0 -1" />
    <limit
      lower="-1.57"
      upper="1.57"
      effort="0"
      velocity="1.0" />
  </joint>
  <link
    name="Link_4">
    <inertial>
      <origin
        xyz="0.117611088125661 -0.00465390768768329 -0.0126351160550418"
        rpy="0 0 0" />
      <mass
        value="3.03420182472638" />
      <inertia
        ixx="0.00759463502549575"
        ixy="-0.000651466560769693"
        ixz="-0.00231146667953279"
        iyy="0.018710801302445"
        iyz="-0.000512349600738883"
        izz="0.0167149149872345" />
    </inertial>
    <visual>
      <origin
        xyz="0 0 0"
        rpy="0 0 0" />
      <geometry>
        <mesh
          filename="package://manipulator_description_pkg/meshes/Link_4.stl" />
      </geometry>
      <material
        name="">
        <color
          rgba="0.752941176470588 0.752941176470588 0.752941176470588 1" />
      </material>
    </visual>
    <collision>
      <origin
        xyz="0 0 0"
        rpy="0 0 0" />
      <geometry>
        <mesh
          filename="package://manipulator_description_pkg/meshes/Link_4.stl" />
      </geometry>
    </collision>
  </link>
  <joint
    name="J4"
    type="revolute">
    <origin
      xyz="-0.215952 0 0"
      rpy="1.57079632679489 0 -3.14159265358979" />
    <parent
      link="Link_3" />
    <child
      link="Link_4" />
    <axis
      xyz="0 0 1" />
    <limit
      lower="-1.57"
      upper="1.57"
      effort="0"
      velocity="1.0" />
  </joint>
  <link
    name="Link_5">
    <inertial>
      <origin
        xyz="-0.00148897959108596 -0.00120397697869818 0.0404727520489701"
        rpy="0 0 0" />
      <mass
        value="0.563703905469621" />
      <inertia
        ixx="0.000963926045704061"
        ixy="7.52875130487018E-07"
        ixz="0.000355099471515132"
        iyy="0.00138379947869169"
        iyz="-2.28824081909559E-07"
        izz="0.000805257616964053" />
    </inertial>
    <visual>
      <origin
        xyz="0 0 0"
        rpy="0 0 0" />
      <geometry>
        <mesh
          filename="package://manipulator_description_pkg/meshes/Link_5.stl" />
      </geometry>
      <material
        name="">
        <color
          rgba="0.752941176470588 0.752941176470588 0.752941176470588 1" />
      </material>
    </visual>
    <collision>
      <origin
        xyz="0 0 0"
        rpy="0 0 0" />
      <geometry>
        <mesh
          filename="package://manipulator_description_pkg/meshes/Link_5.stl" />
      </geometry>
    </collision>
  </link>
  <joint
    name="J5"
    type="revolute">
    <origin
      xyz="0.252768 0 0"
      rpy="1.5707963267949 0 1.5707963267949" />
    <parent
      link="Link_4" />
    <child
      link="Link_5" />
    <axis
      xyz="0 0 1" />
    <limit
      lower="-3.14"
      upper="3.14"
      effort="0"
      velocity="1.0" />
  </joint>
  <link
    name="Link_6">
    <inertial>
      <origin
        xyz="0.0329414421864191 -0.00212848490620032 0.00278032328886195"
        rpy="0 0 0" />
      <mass
        value="1.88848825944127" />
      <inertia
        ixx="0.0019631879180913"
        ixy="7.01170688758701E-06"
        ixz="2.78903497866982E-05"
        iyy="0.00182763223827929"
        iyz="2.26183433374122E-05"
        izz="0.00215440912647321" />
    </inertial>
    <visual>
      <origin
        xyz="0 0 0"
        rpy="0 0 0" />
      <geometry>
        <mesh
          filename="package://manipulator_description_pkg/meshes/Link_6.stl" />
      </geometry>
      <material
        name="">
        <color
          rgba="0.752941176470588 0.752941176470588 0.752941176470588 1" />
      </material>
    </visual>
    <collision>
      <origin
        xyz="0 0 0"
        rpy="0 0 0" />
      <geometry>
        <mesh
          filename="package://manipulator_description_pkg/meshes/Link_6.stl" />
      </geometry>
    </collision>
  </link>
  <joint
    name="J6"
    type="revolute">
    <origin
      xyz="0 0 0.09"
      rpy="3.14159265358979 -1.5707963267949 0" />
    <parent
      link="Link_5" />
    <child
      link="Link_6" />
    <axis
      xyz="0 0 -1" />
    <limit
      lower="-1.57"
      upper="1.57"
      effort="0"
      velocity="1.0" />
  </joint>
  <link
    name="Link_7">
    <inertial>
      <origin
        xyz="-0.00216789338975825 -0.00221996651681478 0.085978156473852"
        rpy="0 0 0" />
      <mass
        value="0.674515078467848" />
      <inertia
        ixx="0.000530705805553587"
        ixy="-5.75819445362227E-05"
        ixz="-6.59533373948588E-06"
        iyy="0.000530644919812234"
        iyz="6.606206783841E-06"
        izz="0.000286424369392125" />
    </inertial>
    <visual>
      <origin
        xyz="0 0 0"
        rpy="0 0 0" />
      <geometry>
        <mesh
          filename="package://manipulator_description_pkg/meshes/Link_7.stl" />
      </geometry>
      <material
        name="">
        <color
          rgba="0.752941176470588 0.752941176470588 0.752941176470588 1" />
      </material>
    </visual>
    <collision>
      <origin
        xyz="0 0 0"
        rpy="0 0 0" />
      <geometry>
        <mesh
          filename="package://manipulator_description_pkg/meshes/Link_7.stl" />
      </geometry>
    </collision>
  </link>
  <joint
    name="J7"
    type="revolute">
    <origin
      xyz="0.1 0 0"
      rpy="0 1.5707963267949 0" />
    <parent
      link="Link_6" />
    <child
      link="Link_7" />
    <axis
      xyz="0 0 -1" />
    <limit
      lower="-3.14"
      upper="3.14"
      effort="0"
      velocity="1.0" />
  </joint>
  
  <ros2_control name="GazeboSimSystem" type="system">
  		<hardware>
  			<plugin>gz_ros2_control/GazeboSimSystem</plugin>
  		</hardware>
  		<joint name="J1">
  			<!--command_interface name="position"/-->
  			<command_interface name="effort"/>
  			<state_interface name="position"/>
  			<state_interface name="velocity"/>
  		</joint>
  		<joint name="J2">
  			<command_interface name="effort"/>
  			<state_interface name="position"/>
  			<state_interface name="velocity"/>
  		</joint>
  		<joint name="J3">
  			<command_interface name="effort"/>
  			<state_interface name="position"/>
  			<state_interface name="velocity"/>
  		</joint>
  		<joint name="J4">
  			<command_interface name="effort"/>
  			<state_interface name="position"/>
  			<state_interface name="velocity"/>
  		</joint>
  		<joint name="J5">
  			<command_interface name="effort"/>
  			<state_interface name="position"/>
  			<state_interface name="velocity"/>
  		</joint>
  		<joint name="J6">
  			<command_interface name="effort"/>
  			<state_interface name="position"/>
  			<state_interface name="velocity"/>
  		</joint>
  		<joint name="J7">
  			<command_interface name="effort"/>
  			<state_interface name="position"/>
  			<state_interface name="velocity"/>
  		</joint>
  </ros2_control>

	<gazebo>
		<plugin filename="libgz_ros2_control-system.so" name="gz_ros2_control::GazeboROS2SimControlPlugin">
			<parameters>/home/thamiris/Desktop/ISI/ROS_Simulations/Impedance_Control/manipulator_ws/src/manipulator_description_pkg/controllers/controllers.yaml</parameters>
			<controller_manager_prefix_node_name>controller_manager</controller_manager_prefix_node_name>
		</plugin>
	</gazebo>
</robot>
